2025-08-12 22:29:14.503 | [13/Aug/2025 01:29:14] "GET /admin/oraculo/fluxoconversa/ HTTP/1.1" 200 15275
2025-08-12 22:29:21.231 | Internal Server Error: /admin/oraculo/departamento/
2025-08-12 22:29:21.231 | Traceback (most recent call last):
2025-08-12 22:29:21.231 |   File "/app/.venv/lib/python3.13/site-packages/django/db/backends/utils.py", line 105, in _execute
2025-08-12 22:29:21.231 |     return self.cursor.execute(sql, params)
2025-08-12 22:29:21.231 |            ~~~~~~~~~~~~~~~~~~~^^^^^^^^^^^^^
2025-08-12 22:29:21.231 |   File "/app/.venv/lib/python3.13/site-packages/psycopg/cursor.py", line 97, in execute
2025-08-12 22:29:21.231 |     raise ex.with_traceback(None)
2025-08-12 22:29:21.231 | psycopg.errors.UndefinedTable: relation "oraculo_departamento" does not exist
2025-08-12 22:29:21.231 | LINE 1: SELECT COUNT(*) AS "__count" FROM "oraculo_departamento"
2025-08-12 22:29:21.231 |                                           ^
2025-08-12 22:29:21.231 | 
2025-08-12 22:29:21.231 | The above exception was the direct cause of the following exception:
2025-08-12 22:29:21.231 | 
2025-08-12 22:29:21.231 | Traceback (most recent call last):
2025-08-12 22:29:21.231 |   File "/app/.venv/lib/python3.13/site-packages/django/core/handlers/exception.py", line 55, in inner
2025-08-12 22:29:21.231 |     response = get_response(request)
2025-08-12 22:29:21.231 |   File "/app/.venv/lib/python3.13/site-packages/django/core/handlers/base.py", line 197, in _get_response
2025-08-12 22:29:21.231 |     response = wrapped_callback(request, *callback_args, **callback_kwargs)
2025-08-12 22:29:21.231 |   File "/app/.venv/lib/python3.13/site-packages/django/contrib/admin/options.py", line 719, in wrapper
2025-08-12 22:29:21.231 |     return self.admin_site.admin_view(view)(*args, **kwargs)
2025-08-12 22:29:21.231 |            ~~~~~~~~~~~~~~~~~~~~~~~~~~~~~~~~^^^^^^^^^^^^^^^^^
2025-08-12 22:29:21.231 |   File "/app/.venv/lib/python3.13/site-packages/django/utils/decorators.py", line 192, in _view_wrapper
2025-08-12 22:29:21.231 |     result = _process_exception(request, e)
2025-08-12 22:29:21.231 |   File "/app/.venv/lib/python3.13/site-packages/django/utils/decorators.py", line 190, in _view_wrapper
2025-08-12 22:29:21.231 |     response = view_func(request, *args, **kwargs)
2025-08-12 22:29:21.231 |   File "/app/.venv/lib/python3.13/site-packages/django/views/decorators/cache.py", line 80, in _view_wrapper
2025-08-12 22:29:21.231 |     response = view_func(request, *args, **kwargs)
2025-08-12 22:29:21.231 |   File "/app/.venv/lib/python3.13/site-packages/django/contrib/admin/sites.py", line 246, in inner
2025-08-12 22:29:21.231 |     return view(request, *args, **kwargs)
2025-08-12 22:29:21.231 |   File "/app/.venv/lib/python3.13/site-packages/django/utils/decorators.py", line 48, in _wrapper
2025-08-12 22:29:21.231 |     return bound_method(*args, **kwargs)
2025-08-12 22:29:21.231 |   File "/app/.venv/lib/python3.13/site-packages/django/utils/decorators.py", line 192, in _view_wrapper
2025-08-12 22:29:21.231 |     result = _process_exception(request, e)
2025-08-12 22:29:21.231 |   File "/app/.venv/lib/python3.13/site-packages/django/utils/decorators.py", line 190, in _view_wrapper
2025-08-12 22:29:21.231 |     response = view_func(request, *args, **kwargs)
2025-08-12 22:29:21.231 |   File "/app/.venv/lib/python3.13/site-packages/django/contrib/admin/options.py", line 2024, in changelist_view
2025-08-12 22:29:21.231 |     cl = self.get_changelist_instance(request)
2025-08-12 22:29:21.231 |   File "/app/.venv/lib/python3.13/site-packages/django/contrib/admin/options.py", line 867, in get_changelist_instance
2025-08-12 22:29:21.231 |     return ChangeList(
2025-08-12 22:29:21.231 |         request,
2025-08-12 22:29:21.231 |     ...<12 lines>...
2025-08-12 22:29:21.231 |         self.search_help_text,
2025-08-12 22:29:21.231 |     )
2025-08-12 22:29:21.231 |   File "/app/.venv/lib/python3.13/site-packages/django/contrib/admin/views/main.py", line 146, in __init__
2025-08-12 22:29:21.231 |     self.get_results(request)
2025-08-12 22:29:21.231 |     ~~~~~~~~~~~~~~~~^^^^^^^^^
2025-08-12 22:29:21.231 |   File "/app/.venv/lib/python3.13/site-packages/django/contrib/admin/views/main.py", line 313, in get_results
2025-08-12 22:29:21.231 |     result_count = paginator.count
2025-08-12 22:29:21.231 |                    ^^^^^^^^^^^^^^^
2025-08-12 22:29:21.231 |   File "/app/.venv/lib/python3.13/site-packages/django/utils/functional.py", line 47, in __get__
2025-08-12 22:29:21.231 |     res = instance.__dict__[self.name] = self.func(instance)
2025-08-12 22:29:21.231 |                                          ~~~~~~~~~^^^^^^^^^^
2025-08-12 22:29:21.231 |   File "/app/.venv/lib/python3.13/site-packages/django/core/paginator.py", line 110, in count
2025-08-12 22:29:21.231 |     return c()
2025-08-12 22:29:21.231 |   File "/app/.venv/lib/python3.13/site-packages/django/db/models/query.py", line 604, in count
2025-08-12 22:29:21.231 |     return self.query.get_count(using=self.db)
2025-08-12 22:29:21.231 |            ~~~~~~~~~~~~~~~~~~~~^^^^^^^^^^^^^^^
2025-08-12 22:29:21.231 |   File "/app/.venv/lib/python3.13/site-packages/django/db/models/sql/query.py", line 644, in get_count
2025-08-12 22:29:21.231 |     return obj.get_aggregation(using, {"__count": Count("*")})["__count"]
2025-08-12 22:29:21.231 |            ~~~~~~~~~~~~~~~~~~~^^^^^^^^^^^^^^^^^^^^^^^^^^^^^^^^
2025-08-12 22:29:21.231 |   File "/app/.venv/lib/python3.13/site-packages/django/db/models/sql/query.py", line 626, in get_aggregation
2025-08-12 22:29:21.231 |     result = compiler.execute_sql(SINGLE)
2025-08-12 22:29:21.231 |   File "/app/.venv/lib/python3.13/site-packages/django/db/models/sql/compiler.py", line 1623, in execute_sql
2025-08-12 22:29:21.231 |     cursor.execute(sql, params)
2025-08-12 22:29:21.231 |     ~~~~~~~~~~~~~~^^^^^^^^^^^^^
2025-08-12 22:29:21.231 |   File "/app/.venv/lib/python3.13/site-packages/django/db/backends/utils.py", line 122, in execute
2025-08-12 22:29:21.231 |     return super().execute(sql, params)
2025-08-12 22:29:21.231 |            ~~~~~~~~~~~~~~~^^^^^^^^^^^^^
2025-08-12 22:29:21.231 |   File "/app/.venv/lib/python3.13/site-packages/django/db/backends/utils.py", line 79, in execute
2025-08-12 22:29:21.231 |     return self._execute_with_wrappers(
2025-08-12 22:29:21.231 |            ~~~~~~~~~~~~~~~~~~~~~~~~~~~^
2025-08-12 22:29:21.231 |         sql, params, many=False, executor=self._execute
2025-08-12 22:29:21.231 |         ^^^^^^^^^^^^^^^^^^^^^^^^^^^^^^^^^^^^^^^^^^^^^^^
2025-08-12 22:29:21.231 |     )
2025-08-12 22:29:21.231 |     ^
2025-08-12 22:29:21.231 |   File "/app/.venv/lib/python3.13/site-packages/django/db/backends/utils.py", line 92, in _execute_with_wrappers
2025-08-12 22:29:21.231 |     return executor(sql, params, many, context)
2025-08-12 22:29:21.231 |   File "/app/.venv/lib/python3.13/site-packages/django/db/backends/utils.py", line 100, in _execute
2025-08-12 22:29:21.231 |     with self.db.wrap_database_errors:
2025-08-12 22:29:21.231 |          ^^^^^^^^^^^^^^^^^^^^^^^^^^^^
2025-08-12 22:29:21.231 |   File "/app/.venv/lib/python3.13/site-packages/django/db/utils.py", line 91, in __exit__
2025-08-12 22:29:21.231 |     raise dj_exc_value.with_traceback(traceback) from exc_value
2025-08-12 22:29:21.231 |   File "/app/.venv/lib/python3.13/site-packages/django/db/backends/utils.py", line 105, in _execute
2025-08-12 22:29:21.231 |     return self.cursor.execute(sql, params)
2025-08-12 22:29:21.231 |            ~~~~~~~~~~~~~~~~~~~^^^^^^^^^^^^^
2025-08-12 22:29:21.231 |   File "/app/.venv/lib/python3.13/site-packages/psycopg/cursor.py", line 97, in execute
2025-08-12 22:29:21.231 |     raise ex.with_traceback(None)
2025-08-12 22:29:21.231 | django.db.utils.ProgrammingError: relation "oraculo_departamento" does not exist
2025-08-12 22:29:21.231 | LINE 1: SELECT COUNT(*) AS "__count" FROM "oraculo_departamento"
2025-08-12 22:29:21.231 |                                           ^
2025-08-12 22:29:21.231 | ERROR:django.request:Internal Server Error: /admin/oraculo/departamento/
2025-08-12 22:29:21.231 | Traceback (most recent call last):
2025-08-12 22:29:21.231 |   File "/app/.venv/lib/python3.13/site-packages/django/db/backends/utils.py", line 105, in _execute
2025-08-12 22:29:21.231 |     return self.cursor.execute(sql, params)
2025-08-12 22:29:21.231 |            ~~~~~~~~~~~~~~~~~~~^^^^^^^^^^^^^
2025-08-12 22:29:21.231 |   File "/app/.venv/lib/python3.13/site-packages/psycopg/cursor.py", line 97, in execute
2025-08-12 22:29:21.231 |     raise ex.with_traceback(None)
2025-08-12 22:29:21.231 | psycopg.errors.UndefinedTable: relation "oraculo_departamento" does not exist
2025-08-12 22:29:21.231 | LINE 1: SELECT COUNT(*) AS "__count" FROM "oraculo_departamento"
2025-08-12 22:29:21.231 |                                           ^
2025-08-12 22:29:21.231 | 
2025-08-12 22:29:21.231 | The above exception was the direct cause of the following exception:
2025-08-12 22:29:21.231 | 
2025-08-12 22:29:21.231 | Traceback (most recent call last):
2025-08-12 22:29:21.231 |   File "/app/.venv/lib/python3.13/site-packages/django/core/handlers/exception.py", line 55, in inner
2025-08-12 22:29:21.231 |     response = get_response(request)
2025-08-12 22:29:21.231 |   File "/app/.venv/lib/python3.13/site-packages/django/core/handlers/base.py", line 197, in _get_response
2025-08-12 22:29:21.231 |     response = wrapped_callback(request, *callback_args, **callback_kwargs)
2025-08-12 22:29:21.231 |   File "/app/.venv/lib/python3.13/site-packages/django/contrib/admin/options.py", line 719, in wrapper
2025-08-12 22:29:21.231 |     return self.admin_site.admin_view(view)(*args, **kwargs)
2025-08-12 22:29:21.231 |            ~~~~~~~~~~~~~~~~~~~~~~~~~~~~~~~~^^^^^^^^^^^^^^^^^
2025-08-12 22:29:21.231 |   File "/app/.venv/lib/python3.13/site-packages/django/utils/decorators.py", line 192, in _view_wrapper
2025-08-12 22:29:21.231 |     result = _process_exception(request, e)
2025-08-12 22:29:21.231 |   File "/app/.venv/lib/python3.13/site-packages/django/utils/decorators.py", line 190, in _view_wrapper
2025-08-12 22:29:21.231 |     response = view_func(request, *args, **kwargs)
2025-08-12 22:29:21.231 |   File "/app/.venv/lib/python3.13/site-packages/django/views/decorators/cache.py", line 80, in _view_wrapper
2025-08-12 22:29:21.231 |     response = view_func(request, *args, **kwargs)
2025-08-12 22:29:21.231 |   File "/app/.venv/lib/python3.13/site-packages/django/contrib/admin/sites.py", line 246, in inner
2025-08-12 22:29:21.231 |     return view(request, *args, **kwargs)
2025-08-12 22:29:21.231 |   File "/app/.venv/lib/python3.13/site-packages/django/utils/decorators.py", line 48, in _wrapper
2025-08-12 22:29:21.231 |     return bound_method(*args, **kwargs)
2025-08-12 22:29:21.231 |   File "/app/.venv/lib/python3.13/site-packages/django/utils/decorators.py", line 192, in _view_wrapper
2025-08-12 22:29:21.231 |     result = _process_exception(request, e)
2025-08-12 22:29:21.231 |   File "/app/.venv/lib/python3.13/site-packages/django/utils/decorators.py", line 190, in _view_wrapper
2025-08-12 22:29:21.231 |     response = view_func(request, *args, **kwargs)
2025-08-12 22:29:21.231 |   File "/app/.venv/lib/python3.13/site-packages/django/contrib/admin/options.py", line 2024, in changelist_view
2025-08-12 22:29:21.231 |     cl = self.get_changelist_instance(request)
2025-08-12 22:29:21.231 |   File "/app/.venv/lib/python3.13/site-packages/django/contrib/admin/options.py", line 867, in get_changelist_instance
2025-08-12 22:29:21.231 |     return ChangeList(
2025-08-12 22:29:21.231 |         request,
2025-08-12 22:29:21.231 |     ...<12 lines>...
2025-08-12 22:29:21.231 |         self.search_help_text,
2025-08-12 22:29:21.231 |     )
2025-08-12 22:29:21.231 |   File "/app/.venv/lib/python3.13/site-packages/django/contrib/admin/views/main.py", line 146, in __init__
2025-08-12 22:29:21.231 |     self.get_results(request)
2025-08-12 22:29:21.231 |     ~~~~~~~~~~~~~~~~^^^^^^^^^
2025-08-12 22:29:21.231 |   File "/app/.venv/lib/python3.13/site-packages/django/contrib/admin/views/main.py", line 313, in get_results
2025-08-12 22:29:21.231 |     result_count = paginator.count
2025-08-12 22:29:21.231 |                    ^^^^^^^^^^^^^^^
2025-08-12 22:29:21.231 |   File "/app/.venv/lib/python3.13/site-packages/django/utils/functional.py", line 47, in __get__
2025-08-12 22:29:21.231 |     res = instance.__dict__[self.name] = self.func(instance)
2025-08-12 22:29:21.231 |                                          ~~~~~~~~~^^^^^^^^^^
2025-08-12 22:29:21.231 |   File "/app/.venv/lib/python3.13/site-packages/django/core/paginator.py", line 110, in count
2025-08-12 22:29:21.231 |     return c()
2025-08-12 22:29:21.231 |   File "/app/.venv/lib/python3.13/site-packages/django/db/models/query.py", line 604, in count
2025-08-12 22:29:21.231 |     return self.query.get_count(using=self.db)
2025-08-12 22:29:21.231 |            ~~~~~~~~~~~~~~~~~~~~^^^^^^^^^^^^^^^
2025-08-12 22:29:21.231 |   File "/app/.venv/lib/python3.13/site-packages/django/db/models/sql/query.py", line 644, in get_count
2025-08-12 22:29:21.231 |     return obj.get_aggregation(using, {"__count": Count("*")})["__count"]
2025-08-12 22:29:21.231 |            ~~~~~~~~~~~~~~~~~~~^^^^^^^^^^^^^^^^^^^^^^^^^^^^^^^^
2025-08-12 22:29:21.231 |   File "/app/.venv/lib/python3.13/site-packages/django/db/models/sql/query.py", line 626, in get_aggregation
2025-08-12 22:29:21.231 |     result = compiler.execute_sql(SINGLE)
2025-08-12 22:29:21.231 |   File "/app/.venv/lib/python3.13/site-packages/django/db/models/sql/compiler.py", line 1623, in execute_sql
2025-08-12 22:29:21.231 |     cursor.execute(sql, params)
2025-08-12 22:29:21.231 |     ~~~~~~~~~~~~~~^^^^^^^^^^^^^
2025-08-12 22:29:21.231 |   File "/app/.venv/lib/python3.13/site-packages/django/db/backends/utils.py", line 122, in execute
2025-08-12 22:29:21.231 |     return super().execute(sql, params)
2025-08-12 22:29:21.231 |            ~~~~~~~~~~~~~~~^^^^^^^^^^^^^
2025-08-12 22:29:21.231 |   File "/app/.venv/lib/python3.13/site-packages/django/db/backends/utils.py", line 79, in execute
2025-08-12 22:29:21.231 |     return self._execute_with_wrappers(
2025-08-12 22:29:21.231 |            ~~~~~~~~~~~~~~~~~~~~~~~~~~~^
2025-08-12 22:29:21.231 |         sql, params, many=False, executor=self._execute
2025-08-12 22:29:21.231 |         ^^^^^^^^^^^^^^^^^^^^^^^^^^^^^^^^^^^^^^^^^^^^^^^
2025-08-12 22:29:21.231 |     )
2025-08-12 22:29:21.231 |     ^
2025-08-12 22:29:21.231 |   File "/app/.venv/lib/python3.13/site-packages/django/db/backends/utils.py", line 92, in _execute_with_wrappers
2025-08-12 22:29:21.231 |     return executor(sql, params, many, context)
2025-08-12 22:29:21.231 |   File "/app/.venv/lib/python3.13/site-packages/django/db/backends/utils.py", line 100, in _execute
2025-08-12 22:29:21.231 |     with self.db.wrap_database_errors:
2025-08-12 22:29:21.231 |          ^^^^^^^^^^^^^^^^^^^^^^^^^^^^
2025-08-12 22:29:21.231 |   File "/app/.venv/lib/python3.13/site-packages/django/db/utils.py", line 91, in __exit__
2025-08-12 22:29:21.231 |     raise dj_exc_value.with_traceback(traceback) from exc_value
2025-08-12 22:29:21.231 |   File "/app/.venv/lib/python3.13/site-packages/django/db/backends/utils.py", line 105, in _execute
2025-08-12 22:29:21.231 |     return self.cursor.execute(sql, params)
2025-08-12 22:29:21.231 |            ~~~~~~~~~~~~~~~~~~~^^^^^^^^^^^^^
2025-08-12 22:29:21.231 |   File "/app/.venv/lib/python3.13/site-packages/psycopg/cursor.py", line 97, in execute
2025-08-12 22:29:21.231 |     raise ex.with_traceback(None)
2025-08-12 22:29:21.231 | django.db.utils.ProgrammingError: relation "oraculo_departamento" does not exist
2025-08-12 22:29:21.231 | LINE 1: SELECT COUNT(*) AS "__count" FROM "oraculo_departamento"
2025-08-12 22:29:21.231 |                                           ^
2025-08-12 22:29:21.232 | [13/Aug/2025 01:29:21] "GET /admin/oraculo/departamento/ HTTP/1.1" 500 217667
2025-08-12 22:29:24.677 | [13/Aug/2025 01:29:24] "GET /admin/ HTTP/1.1" 302 0